Workbook
Name V_Mois: DATA_VENTES!$A$2:$A$9516
Name V_Ex: DATA_VENTES!$B$2:$B$9516
Name V_Mag: DATA_VENTES!$C$2:$C$9516
Name V_Reg: DATA_VENTES!$D$2:$D$9516
Name V_Canal: DATA_VENTES!$E$2:$E$9516
Name V_Jours: DATA_VENTES!$F$2:$F$9516
Name V_Tickets: DATA_VENTES!$G$2:$G$9516
Name V_Articles: DATA_VENTES!$H$2:$H$9516
Name V_CABrut: DATA_VENTES!$I$2:$I$9516
Name V_Remises: DATA_VENTES!$J$2:$J$9516
Name V_CANet: DATA_VENTES!$K$2:$K$9516
Name V_Cout: DATA_VENTES!$L$2:$L$9516
Name B_Mois: DATA_BUDGET!$A$2:$A$2881
Name B_Ex: DATA_BUDGET!$B$2:$B$2881
Name B_Mag: DATA_BUDGET!$C$2:$C$2881
Name B_Reg: DATA_BUDGET!$D$2:$D$2881
Name B_Budget: DATA_BUDGET!$E$2:$E$2881
Name S_Mois: DATA_STOCKS!$A$2:$A$2831
Name S_Ex: DATA_STOCKS!$B$2:$B$2831
Name S_Mag: DATA_STOCKS!$C$2:$C$2831
Name S_Sorties: DATA_STOCKS!$D$2:$D$2831
Name S_Pertes: DATA_STOCKS!$E$2:$E$2831
Name A_Mois: DATA_ACHATS!$A$2:$A$333
Name A_Ex: DATA_ACHATS!$B$2:$B$333
Name A_Fourn: DATA_ACHATS!$C$2:$C$333
Name A_Lignes: DATA_ACHATS!$D$2:$D$333
Name A_Livrees: DATA_ACHATS!$E$2:$E$333
Name A_Retard: DATA_ACHATS!$F$2:$F$333
Name A_EnRetard: DATA_ACHATS!$G$2:$G$333
Name A_Montant: DATA_ACHATS!$H$2:$H$333
Name AM_Ex: DATA_ACHATS_MAG!$A$2:$A$239
Name AM_Mag: DATA_ACHATS_MAG!$B$2:$B$239
Name AM_Reel: DATA_ACHATS_MAG!$C$2:$C$239
Name AM_Reseau: DATA_ACHATS_MAG!$D$2:$D$239
Name R_Mois: DATA_RH!$A$2:$A$2831
Name R_Ex: DATA_RH!$B$2:$B$2831
Name R_Mag: DATA_RH!$C$2:$C$2831
Name R_Salaries: DATA_RH!$D$2:$D$2831
Name R_Heures: DATA_RH!$E$2:$E$2831
Name R_HS: DATA_RH!$F$2:$F$2831
Name R_Abs: DATA_RH!$G$2:$G$2831
Name X_Ex: DATA_MIX!$A$2:$A$9993
Name X_Mag: DATA_MIX!$B$2:$B$9993
Name X_Prod: DATA_MIX!$C$2:$C$9993
Name X_Qte: DATA_MIX!$D$2:$D$9993
Name X_CA: DATA_MIX!$E$2:$E$9993
Name X_Cout: DATA_MIX!$F$2:$F$9993
Name M_Code: REF_MAGASINS!$A$2:$A$121
Name M_Nom: REF_MAGASINS!$B$2:$B$121
Name M_Ville: REF_MAGASINS!$C$2:$C$121
Name M_Region: REF_MAGASINS!$D$2:$D$121
Name M_Type: REF_MAGASINS!$E$2:$E$121
Name M_Statut: REF_MAGASINS!$F$2:$F$121
Name M_Surface: REF_MAGASINS!$G$2:$G$121
Name M_Places: REF_MAGASINS!$H$2:$H$121
Name M_Drive: REF_MAGASINS!$I$2:$I$121
Name M_Franchise: REF_MAGASINS!$J$2:$J$121
Name M_Ouv: REF_MAGASINS!$K$2:$K$121
Name M_Ferm: REF_MAGASINS!$L$2:$L$121
Name P_Code: REF_PRODUITS!$A$2:$A$43

Sheet DASHBOARD
B1: HORIZON_CONTRAT — PILOTAGE RÉSEAU
B2: ="Exercice "&Exercice_Courant&" (sept.–août) · comparatif "&Exercice_Precedent&" · "&D_Nb_Magasins&" points de vente dans le filtre"
B4: Région | C4: Toutes | G4: Canal | H4: Tous | L4: Les deux filtres pilotent les cartes, la courbe et le classement. Le budget n'existe pas par canal.
B6: CA NET HT | E6: CROISSANCE COMPARABLE | H6: TAUX DE MARGE BRUTE | K6: TICKETS | N6: TICKET MOYEN HT | Q6: ATTEINTE BUDGET 2026
B7: =D_CA_N | E7: =D_Delta_Comp | H7: =D_Taux_N | K7: =D_Tickets_N | N7: =D_TM_N | Q7: =IF(Canal_Filtre="Tous",D_Atteinte,"n/a")
B9: =IF(D_Delta_CA>=0,"+","")&FIXED(D_Delta_CA*100,1)&" % vs N-1" | E9: =D_Nb_Comparables&" magasins comparables" | H9: =IF(D_Delta_Taux_pt>=0,"+","")&FIXED(D_Delta_Taux_pt,2)&" pt vs N-1" | K9: =IF(D_Delta_Tickets>=0,"+","")&FIXED(D_Delta_Tickets*100,1)&" % vs N-1" | N9: =IF(D_Delta_TM>=0,"+","")&FIXED(D_Delta_TM*100,1)&" % — dont prix +"&FIXED(Hausse_Tarifaire*100,1)&" %" | Q9: =IF(Canal_Filtre="Tous",D_Nb_Sous_Objectif&" magasins sous "&FIXED(Seuil_Atteinte_Budget*100,0)&" %","Budget non ventilé par canal")
B30: Magasins sous surveillance — taux de marge les plus faibles du filtre | O30: Constat à instruire
B31: Code | D31: Ville | F31: Région | H31: CA net | J31: Taux de marge | L31: Écart réseau | O31: =D_Nb_Sous_Seuil&" magasin(s) sous le seuil d'alerte de "&FIXED(D_Seuil_Taux_Alerte*100,2)&" % (réseau − "&FIXED(Seuil_Alerte_Marge_Pt*100,0)&" pt). Le plus bas, "&CALC_DASH!D70&" ("&CALC_DASH!E70&"), est à "&FIXED(CALC_DASH!H70*100,2)&" %, soit "&FIXED(-CALC_DASH!I70,2)&" pt sous le réseau. À croiser avec les pertes de stock et les prix d'achat : voir FICHE_MAGASIN, bloc Diagnostic."
B32: =CALC_DASH!D70 | D32: =CALC_DASH!E70 | F32: =CALC_DASH!F70 | H32: =CALC_DASH!G70 | J32: =CALC_DASH!H70 | L32: =CALC_DASH!I70
B33: =CALC_DASH!D71 | D33: =CALC_DASH!E71 | F33: =CALC_DASH!F71 | H33: =CALC_DASH!G71 | J33: =CALC_DASH!H71 | L33: =CALC_DASH!I71
B34: =CALC_DASH!D72 | D34: =CALC_DASH!E72 | F34: =CALC_DASH!F72 | H34: =CALC_DASH!G72 | J34: =CALC_DASH!H72 | L34: =CALC_DASH!I72
B35: =CALC_DASH!D73 | D35: =CALC_DASH!E73 | F35: =CALC_DASH!F73 | H35: =CALC_DASH!G73 | J35: =CALC_DASH!H73 | L35: =CALC_DASH!I73
B36: =CALC_DASH!D74 | D36: =CALC_DASH!E74 | F36: =CALC_DASH!F74 | H36: =CALC_DASH!G74 | J36: =CALC_DASH!H74 | L36: =CALC_DASH!I74
B37: =CALC_DASH!D75 | D37: =CALC_DASH!E75 | F37: =CALC_DASH!F75 | H37: =CALC_DASH!G75 | J37: =CALC_DASH!H75 | L37: =CALC_DASH!I75
B39: ="Seuil d'alerte : taux de marge du réseau ("&FIXED(D_Taux_Reseau*100,2)&" %) moins "&FIXED(Seuil_Alerte_Marge_Pt*100,0)&" pt. Barres de données à échelle fixe 55 %–72 % pour rester comparables d'un filtre à l'autre."

Sheet FICHE_MAGASIN
B1: FICHE MAGASIN
B2: ="Exercice "&Exercice_Courant&" — toutes les valeurs sont des formules pilotées par la cellule Mag_Selectionne (E4)"
B4: Région | C4: Sud-Est | E4: HC-115 | F4: =IF(F_Valide,INDEX(M_Ville,F_Ref),"") | H4: =IF(F_Valide,"","Sélectionne un magasin de la région "&Region_Fiche&" dans la liste en E4.")
B6: =IF(F_Valide,INDEX(M_Ville,F_Ref)&" — "&INDEX(M_Type,F_Ref),"") | G6: CA NET HT | I6: TAUX DE MARGE | K6: TICKETS | M6: TICKET MOYEN HT | O6: ATTEINTE BUDGET 2026
G7: =IF(F_Valide,INDEX(CM_CA_Net_N,F_Ligne),"") | I7: =IF(F_Valide,INDEX(CM_Taux_Marge_N,F_Ligne),"") | K7: =IF(F_Valide,INDEX(CM_Tickets_N,F_Ligne),"") | M7: =IF(F_Valide,INDEX(CM_Ticket_Moyen_N,F_Ligne),"") | O7: =IF(F_Valide,INDEX(CM_Atteinte_Budget,F_Ligne),"")
B8: Code | C8: =IF(F_Valide,Mag_Selectionne,"")
B9: Nom | C9: =IF(F_Valide,INDEX(M_Nom,F_Ref),"") | G9: =IF(F_Valide,IF(ISNUMBER(INDEX(CM_Delta_CA,F_Ligne)),IF(INDEX(CM_Delta_CA,F_Ligne)>=0,"+","")&FIXED(INDEX(CM_Delta_CA,F_Ligne)*100,1)&" % vs N-1","ouvert en cours de N-1"),"") | I9: =IF(F_Valide,IF(INDEX(CM_Taux_Marge_N,F_Ligne)>=D_Taux_Reseau,"+","")&FIXED((INDEX(CM_Taux_Marge_N,F_Ligne)-D_Taux_Reseau)*100,2)&" pt vs réseau","") | K9: =IF(F_Valide,FIXED(INDEX(CM_Tickets_N,F_Ligne)/INDEX(CM_Jours_Ouverts_N,F_Ligne),0)&" par jour ouvert","") | M9: =IF(F_Valide,"réseau : "&FIXED(D_TM_Reseau,2)&" €","") | O9: =IF(F_Valide,IF(INDEX(CM_Reel_2026,F_Ligne)>=INDEX(CM_Budget_2026,F_Ligne),"+","")&FIXED((INDEX(CM_Reel_2026,F_Ligne)-INDEX(CM_Budget_2026,F_Ligne))/1000,0)&" k€ sur janv.–août","")
B10: Région | C10: =IF(F_Valide,INDEX(M_Region,F_Ref),"")
B11: Statut | C11: =IF(F_Valide,INDEX(M_Statut,F_Ref),"") | G11: Position dans le réseau (rang sur l'ensemble des magasins)
B12: Surface | C12: =IF(F_Valide,INDEX(M_Surface,F_Ref),"") | G12: Taux de marge | J12: CA net | M12: Ticket moyen | P12: Perte de stock
B13: Drive | C13: =IF(F_Valide,INDEX(M_Drive,F_Ref),"") | G13: =IF(F_Valide,"rang "&INDEX(CM_Rang_Marge,F_Ligne)&"/"&COUNT(CM_Rang_Marge),"") | J13: =IF(F_Valide,"rang "&INDEX(CM_Rang_CA,F_Ligne)&"/"&COUNT(CM_Rang_CA),"") | M13: =IF(F_Valide,"rang "&INDEX(CM_Rang_Ticket_Moyen,F_Ligne)&"/"&COUNT(CM_Rang_Ticket_Moyen),"") | P13: =IF(F_Valide,"rang "&INDEX(CM_Rang_Perte,F_Ligne)&"/"&COUNT(CM_Rang_Perte),"")
B14: Franchisé | C14: =IF(F_Valide,INDEX(M_Franchise,F_Ref),"") | G14: Rang 1 = meilleur : taux, CA et ticket moyen les plus élevés, taux de perte le plus faible.
B15: Ouverture | C15: =IF(F_Valide,INDEX(M_Ouv,F_Ref),"")
B16: Fermeture | C16: =IF(F_Valide,IF(INDEX(M_Ferm,F_Ref)="","—",INDEX(M_Ferm,F_Ref)),"") | G16: CA net mensuel (barres, k€) et taux de marge (courbe, %)
B19: Top 6 produits — CA et marge
B20: Produit | D20: CA net | E20: Marge
B21: =IF(F_Valide,CALC_FICHE!D73,"") | D21: =IF(F_Valide,CALC_FICHE!F73,"") | E21: =IF(F_Valide,CALC_FICHE!G73,"")
B22: =IF(F_Valide,CALC_FICHE!D74,"") | D22: =IF(F_Valide,CALC_FICHE!F74,"") | E22: =IF(F_Valide,CALC_FICHE!G74,"")
B23: =IF(F_Valide,CALC_FICHE!D75,"") | D23: =IF(F_Valide,CALC_FICHE!F75,"") | E23: =IF(F_Valide,CALC_FICHE!G75,"")
B24: =IF(F_Valide,CALC_FICHE!D76,"") | D24: =IF(F_Valide,CALC_FICHE!F76,"") | E24: =IF(F_Valide,CALC_FICHE!G76,"")
B25: =IF(F_Valide,CALC_FICHE!D77,"") | D25: =IF(F_Valide,CALC_FICHE!F77,"") | E25: =IF(F_Valide,CALC_FICHE!G77,"")
B26: =IF(F_Valide,CALC_FICHE!D78,"") | D26: =IF(F_Valide,CALC_FICHE!F78,"") | E26: =IF(F_Valide,CALC_FICHE!G78,"")
B27: Rouge sous 58 %, vert au-dessus de 65 %.
B29: Ressources humaines (exercice)
B30: Effectif moyen | E30: =IF(F_Valide,INDEX(CM_Effectif_Moyen_N,F_Ligne),"")
B31: Absence / salarié / mois | E31: =IF(F_Valide,INDEX(CM_Absence_Sal_Mois_N,F_Ligne),"")
B32: Heures sup. / salarié / mois | E32: =IF(F_Valide,INDEX(CM_HS_Sal_Mois_N,F_Ligne),"")
B33: CA net / heure travaillée | E33: =IF(F_Valide,INDEX(CM_CA_par_Heure_N,F_Ligne),"") | G33: Diagnostic automatique — hypothèses testées
G34: Hypothèse | J34: Mesure du magasin | L34: Référence réseau | N34: Verdict
G35: Pertes de stock | J35: =IF(F_Valide,INDEX(CM_Taux_Perte_N,F_Ligne),"") | L35: ="médiane "&FIXED(D_Mediane_Perte_N*100,2)&" %" | N35: =IF(F_Valide,IF(INDEX(CM_Taux_Perte_N,F_Ligne)<=Seuil_Perte_Multiple_Mediane*D_Mediane_Perte_N,"écarté","à instruire"),"")
G36: Prix d'achat fournisseurs | J36: =IF(F_Valide,INDEX(CM_Indice_Prix_Achat,F_Ligne),"") | L36: ="tolérance ±"&FIXED(Tolerance_Prix_Achat*100,0)&" %" | N36: =IF(F_Valide,IF(ABS(INDEX(CM_Indice_Prix_Achat,F_Ligne))<=Tolerance_Prix_Achat,"écarté","à instruire"),"")
G37: Mix canal (part livraison) | J37: =IF(F_Valide,INDEX(CM_Part_Livraison_N,F_Ligne),"") | L37: ="réseau "&FIXED(D_Part_Livraison_Reseau*100,1)&" %" | N37: =IF(F_Valide,IF(ABS(INDEX(CM_Part_Livraison_N,F_Ligne)-D_Part_Livraison_Reseau)<=Tolerance_Mix_Livraison,"écarté","à instruire"),"")
G38: Coût matière consommé | J38: =IF(F_Valide,F_Pente,"") | L38: ="seuil d'alerte "&FIXED(D_Seuil_Taux_Alerte*100,2)&" %" | N38: =IF(F_Valide,IF(INDEX(CM_Taux_Marge_N,F_Ligne)<D_Seuil_Taux_Alerte,"à auditer","conforme"),"")
G40: =IF(NOT(F_Valide),"",IF(INDEX(CM_Taux_Marge_N,F_Ligne)>=D_Seuil_Taux_Alerte,"Taux de marge conforme : "&FIXED(INDEX(CM_Taux_Marge_N,F_Ligne)*100,2)&" % contre "&FIXED(D_Taux_Reseau*100,2)&" % pour le réseau. Pas d'action sur la marge.",IF(AND(N35="écarté",N36="écarté",N37="écarté"),"Le taux de marge est "&FIXED((D_Taux_Reseau-INDEX(CM_Taux_Marge_N,F_Ligne))*100,2)&" pt sous le réseau et recule de "&FIXED(-F_Pente,2)&" pt par mois. Pertes, prix d'achat et mix sont conformes : la dérive vient de la consommation en cuisine (grammages, offerts non enregistrés, démarque non déclarée). Demander un inventaire physique contradictoire et un relevé de grammages.","Le taux de marge est "&FIXED((D_Taux_Reseau-INDEX(CM_Taux_Marge_N,F_Ligne))*100,2)&" pt sous le réseau et au moins une cause externe est identifiée ci-dessus : la traiter avant d'auditer la cuisine.")))

Sheet ANALYSES
B1: ANALYSES — les sept constats du réseau
B2: Chaque bloc répond à une question. La phrase « Constat » est générée par formule : elle change si les données changent.
B4: 1. Quels magasins perdent de la marge ?
B5: ="Taux de marge sur la période A ("&CHOOSE(MONTH(Periode_A_Debut),"janv","févr","mars","avr","mai","juin","juil","août","sept","oct","nov","déc")&"–"&CHOOSE(MONTH(Periode_A_Fin),"janv","févr","mars","avr","mai","juin","juil","août","sept","oct","nov","déc")&" "&YEAR(Periode_A_Fin)&") contre la période B ("&CHOOSE(MONTH(Periode_B_Debut),"janv","févr","mars","avr","mai","juin","juil","août","sept","oct","nov","déc")&"–"&CHOOSE(MONTH(Periode_B_Fin),"janv","févr","mars","avr","mai","juin","juil","août","sept","oct","nov","déc")&" "&YEAR(Periode_B_Fin)&") — les 10 plus forts reculs."
B6: Rang | C6: Ville | D6: Code | E6: Région | F6: Type | G6: Taux A | H6: Taux B | I6: Écart | J6: En dérive
B7: 1 | C7: =INDEX(CM_Ville,MATCH(SMALL(CM_Cle_Derive,1),CM_Cle_Derive,0)) | D7: =INDEX(CM_Code_Magasin,MATCH(SMALL(CM_Cle_Derive,1),CM_Cle_Derive,0)) | E7: =INDEX(CM_Region,MATCH(SMALL(CM_Cle_Derive,1),CM_Cle_Derive,0)) | F7: =INDEX(CM_Type_Emplacement,MATCH(SMALL(CM_Cle_Derive,1),CM_Cle_Derive,0)) | G7: =INDEX(CM_Taux_Marge_A,MATCH(SMALL(CM_Cle_Derive,1),CM_Cle_Derive,0)) | H7: =INDEX(CM_Taux_Marge_B,MATCH(SMALL(CM_Cle_Derive,1),CM_Cle_Derive,0)) | I7: =INDEX(CM_Ecart_A_B_pt,MATCH(SMALL(CM_Cle_Derive,1),CM_Cle_Derive,0)) | J7: =IF(I7<=Seuil_Derive_Marge_Pt,"oui","non")
B8: 2 | C8: =INDEX(CM_Ville,MATCH(SMALL(CM_Cle_Derive,2),CM_Cle_Derive,0)) | D8: =INDEX(CM_Code_Magasin,MATCH(SMALL(CM_Cle_Derive,2),CM_Cle_Derive,0)) | E8: =INDEX(CM_Region,MATCH(SMALL(CM_Cle_Derive,2),CM_Cle_Derive,0)) | F8: =INDEX(CM_Type_Emplacement,MATCH(SMALL(CM_Cle_Derive,2),CM_Cle_Derive,0)) | G8: =INDEX(CM_Taux_Marge_A,MATCH(SMALL(CM_Cle_Derive,2),CM_Cle_Derive,0)) | H8: =INDEX(CM_Taux_Marge_B,MATCH(SMALL(CM_Cle_Derive,2),CM_Cle_Derive,0)) | I8: =INDEX(CM_Ecart_A_B_pt,MATCH(SMALL(CM_Cle_Derive,2),CM_Cle_Derive,0)) | J8: =IF(I8<=Seuil_Derive_Marge_Pt,"oui","non")
B9: 3 | C9: =INDEX(CM_Ville,MATCH(SMALL(CM_Cle_Derive,3),CM_Cle_Derive,0)) | D9: =INDEX(CM_Code_Magasin,MATCH(SMALL(CM_Cle_Derive,3),CM_Cle_Derive,0)) | E9: =INDEX(CM_Region,MATCH(SMALL(CM_Cle_Derive,3),CM_Cle_Derive,0)) | F9: =INDEX(CM_Type_Emplacement,MATCH(SMALL(CM_Cle_Derive,3),CM_Cle_Derive,0)) | G9: =INDEX(CM_Taux_Marge_A,MATCH(SMALL(CM_Cle_Derive,3),CM_Cle_Derive,0)) | H9: =INDEX(CM_Taux_Marge_B,MATCH(SMALL(CM_Cle_Derive,3),CM_Cle_Derive,0)) | I9: =INDEX(CM_Ecart_A_B_pt,MATCH(SMALL(CM_Cle_Derive,3),CM_Cle_Derive,0)) | J9: =IF(I9<=Seuil_Derive_Marge_Pt,"oui","non")
B10: 4 | C10: =INDEX(CM_Ville,MATCH(SMALL(CM_Cle_Derive,4),CM_Cle_Derive,0)) | D10: =INDEX(CM_Code_Magasin,MATCH(SMALL(CM_Cle_Derive,4),CM_Cle_Derive,0)) | E10: =INDEX(CM_Region,MATCH(SMALL(CM_Cle_Derive,4),CM_Cle_Derive,0)) | F10: =INDEX(CM_Type_Emplacement,MATCH(SMALL(CM_Cle_Derive,4),CM_Cle_Derive,0)) | G10: =INDEX(CM_Taux_Marge_A,MATCH(SMALL(CM_Cle_Derive,4),CM_Cle_Derive,0)) | H10: =INDEX(CM_Taux_Marge_B,MATCH(SMALL(CM_Cle_Derive,4),CM_Cle_Derive,0)) | I10: =INDEX(CM_Ecart_A_B_pt,MATCH(SMALL(CM_Cle_Derive,4),CM_Cle_Derive,0)) | J10: =IF(I10<=Seuil_Derive_Marge_Pt,"oui","non")
B11: 5 | C11: =INDEX(CM_Ville,MATCH(SMALL(CM_Cle_Derive,5),CM_Cle_Derive,0)) | D11: =INDEX(CM_Code_Magasin,MATCH(SMALL(CM_Cle_Derive,5),CM_Cle_Derive,0)) | E11: =INDEX(CM_Region,MATCH(SMALL(CM_Cle_Derive,5),CM_Cle_Derive,0)) | F11: =INDEX(CM_Type_Emplacement,MATCH(SMALL(CM_Cle_Derive,5),CM_Cle_Derive,0)) | G11: =INDEX(CM_Taux_Marge_A,MATCH(SMALL(CM_Cle_Derive,5),CM_Cle_Derive,0)) | H11: =INDEX(CM_Taux_Marge_B,MATCH(SMALL(CM_Cle_Derive,5),CM_Cle_Derive,0)) | I11: =INDEX(CM_Ecart_A_B_pt,MATCH(SMALL(CM_Cle_Derive,5),CM_Cle_Derive,0)) | J11: =IF(I11<=Seuil_Derive_Marge_Pt,"oui","non")
B12: 6 | C12: =INDEX(CM_Ville,MATCH(SMALL(CM_Cle_Derive,6),CM_Cle_Derive,0)) | D12: =INDEX(CM_Code_Magasin,MATCH(SMALL(CM_Cle_Derive,6),CM_Cle_Derive,0)) | E12: =INDEX(CM_Region,MATCH(SMALL(CM_Cle_Derive,6),CM_Cle_Derive,0)) | F12: =INDEX(CM_Type_Emplacement,MATCH(SMALL(CM_Cle_Derive,6),CM_Cle_Derive,0)) | G12: =INDEX(CM_Taux_Marge_A,MATCH(SMALL(CM_Cle_Derive,6),CM_Cle_Derive,0)) | H12: =INDEX(CM_Taux_Marge_B,MATCH(SMALL(CM_Cle_Derive,6),CM_Cle_Derive,0)) | I12: =INDEX(CM_Ecart_A_B_pt,MATCH(SMALL(CM_Cle_Derive,6),CM_Cle_Derive,0)) | J12: =IF(I12<=Seuil_Derive_Marge_Pt,"oui","non")
B13: 7 | C13: =INDEX(CM_Ville,MATCH(SMALL(CM_Cle_Derive,7),CM_Cle_Derive,0)) | D13: =INDEX(CM_Code_Magasin,MATCH(SMALL(CM_Cle_Derive,7),CM_Cle_Derive,0)) | E13: =INDEX(CM_Region,MATCH(SMALL(CM_Cle_Derive,7),CM_Cle_Derive,0)) | F13: =INDEX(CM_Type_Emplacement,MATCH(SMALL(CM_Cle_Derive,7),CM_Cle_Derive,0)) | G13: =INDEX(CM_Taux_Marge_A,MATCH(SMALL(CM_Cle_Derive,7),CM_Cle_Derive,0)) | H13: =INDEX(CM_Taux_Marge_B,MATCH(SMALL(CM_Cle_Derive,7),CM_Cle_Derive,0)) | I13: =INDEX(CM_Ecart_A_B_pt,MATCH(SMALL(CM_Cle_Derive,7),CM_Cle_Derive,0)) | J13: =IF(I13<=Seuil_Derive_Marge_Pt,"oui","non")
B14: 8 | C14: =INDEX(CM_Ville,MATCH(SMALL(CM_Cle_Derive,8),CM_Cle_Derive,0)) | D14: =INDEX(CM_Code_Magasin,MATCH(SMALL(CM_Cle_Derive,8),CM_Cle_Derive,0)) | E14: =INDEX(CM_Region,MATCH(SMALL(CM_Cle_Derive,8),CM_Cle_Derive,0)) | F14: =INDEX(CM_Type_Emplacement,MATCH(SMALL(CM_Cle_Derive,8),CM_Cle_Derive,0)) | G14: =INDEX(CM_Taux_Marge_A,MATCH(SMALL(CM_Cle_Derive,8),CM_Cle_Derive,0)) | H14: =INDEX(CM_Taux_Marge_B,MATCH(SMALL(CM_Cle_Derive,8),CM_Cle_Derive,0)) | I14: =INDEX(CM_Ecart_A_B_pt,MATCH(SMALL(CM_Cle_Derive,8),CM_Cle_Derive,0)) | J14: =IF(I14<=Seuil_Derive_Marge_Pt,"oui","non")
B15: 9 | C15: =INDEX(CM_Ville,MATCH(SMALL(CM_Cle_Derive,9),CM_Cle_Derive,0)) | D15: =INDEX(CM_Code_Magasin,MATCH(SMALL(CM_Cle_Derive,9),CM_Cle_Derive,0)) | E15: =INDEX(CM_Region,MATCH(SMALL(CM_Cle_Derive,9),CM_Cle_Derive,0)) | F15: =INDEX(CM_Type_Emplacement,MATCH(SMALL(CM_Cle_Derive,9),CM_Cle_Derive,0)) | G15: =INDEX(CM_Taux_Marge_A,MATCH(SMALL(CM_Cle_Derive,9),CM_Cle_Derive,0)) | H15: =INDEX(CM_Taux_Marge_B,MATCH(SMALL(CM_Cle_Derive,9),CM_Cle_Derive,0)) | I15: =INDEX(CM_Ecart_A_B_pt,MATCH(SMALL(CM_Cle_Derive,9),CM_Cle_Derive,0)) | J15: =IF(I15<=Seuil_Derive_Marge_Pt,"oui","non")
B16: 10 | C16: =INDEX(CM_Ville,MATCH(SMALL(CM_Cle_Derive,10),CM_Cle_Derive,0)) | D16: =INDEX(CM_Code_Magasin,MATCH(SMALL(CM_Cle_Derive,10),CM_Cle_Derive,0)) | E16: =INDEX(CM_Region,MATCH(SMALL(CM_Cle_Derive,10),CM_Cle_Derive,0)) | F16: =INDEX(CM_Type_Emplacement,MATCH(SMALL(CM_Cle_Derive,10),CM_Cle_Derive,0)) | G16: =INDEX(CM_Taux_Marge_A,MATCH(SMALL(CM_Cle_Derive,10),CM_Cle_Derive,0)) | H16: =INDEX(CM_Taux_Marge_B,MATCH(SMALL(CM_Cle_Derive,10),CM_Cle_Derive,0)) | I16: =INDEX(CM_Ecart_A_B_pt,MATCH(SMALL(CM_Cle_Derive,10),CM_Cle_Derive,0)) | J16: =IF(I16<=Seuil_Derive_Marge_Pt,"oui","non")
B18: =COUNTIF(CM_En_Derive,1)&" magasins perdent plus de "&FIXED(-Seuil_Derive_Marge_Pt,0)&" pt de taux de marge, de "&FIXED(SMALL(CM_Ecart_A_B_pt,1),2)&" à "&FIXED(SMALL(CM_Ecart_A_B_pt,COUNTIF(CM_En_Derive,1)),2)&" pt. Le suivant est à "&FIXED(SMALL(CM_Ecart_A_B_pt,COUNTIF(CM_En_Derive,1)+1),2)&" pt : la coupure est franche, ces magasins forment un groupe."
B21: Contrôle du piège « Gare / Aéroport » : taux de marge de l'exercice par type, avec et sans les magasins en dérive.
C22: Type d'emplacement | D22: Nb magasins | E22: dont en dérive | F22: Taux — tous | G22: Taux — hors dérive
C23: Centre commercial | D23: =COUNTIF(CM_Type_Emplacement,C23) | E23: =COUNTIFS(CM_Type_Emplacement,C23,CM_En_Derive,1) | F23: =1-SUMIFS(CM_Cout_N,CM_Type_Emplacement,C23)/SUMIFS(CM_CA_Net_N,CM_Type_Emplacement,C23) | G23: =1-SUMIFS(CM_Cout_N,CM_Type_Emplacement,C23,CM_En_Derive,0)/SUMIFS(CM_CA_Net_N,CM_Type_Emplacement,C23,CM_En_Derive,0)
C24: Centre-ville | D24: =COUNTIF(CM_Type_Emplacement,C24) | E24: =COUNTIFS(CM_Type_Emplacement,C24,CM_En_Derive,1) | F24: =1-SUMIFS(CM_Cout_N,CM_Type_Emplacement,C24)/SUMIFS(CM_CA_Net_N,CM_Type_Emplacement,C24) | G24: =1-SUMIFS(CM_Cout_N,CM_Type_Emplacement,C24,CM_En_Derive,0)/SUMIFS(CM_CA_Net_N,CM_Type_Emplacement,C24,CM_En_Derive,0)
C25: Gare / Aéroport | D25: =COUNTIF(CM_Type_Emplacement,C25) | E25: =COUNTIFS(CM_Type_Emplacement,C25,CM_En_Derive,1) | F25: =1-SUMIFS(CM_Cout_N,CM_Type_Emplacement,C25)/SUMIFS(CM_CA_Net_N,CM_Type_Emplacement,C25) | G25: =1-SUMIFS(CM_Cout_N,CM_Type_Emplacement,C25,CM_En_Derive,0)/SUMIFS(CM_CA_Net_N,CM_Type_Emplacement,C25,CM_En_Derive,0)
C26: Périphérie | D26: =COUNTIF(CM_Type_Emplacement,C26) | E26: =COUNTIFS(CM_Type_Emplacement,C26,CM_En_Derive,1) | F26: =1-SUMIFS(CM_Cout_N,CM_Type_Emplacement,C26)/SUMIFS(CM_CA_Net_N,CM_Type_Emplacement,C26) | G26: =1-SUMIFS(CM_Cout_N,CM_Type_Emplacement,C26,CM_En_Derive,0)/SUMIFS(CM_CA_Net_N,CM_Type_Emplacement,C26,CM_En_Derive,0)
B28: ="Les magasins en dérive se concentrent en « Gare / Aéroport » ("&E25&" sur "&COUNTIF(CM_En_Derive,1)&"), dont le taux paraît plus faible ("&FIXED(F25*100,2)&" %). Hors magasins en dérive, les quatre types se situent entre "&FIXED(MIN(G23:G26)*100,2)&" % et "&FIXED(MAX(G23:G26)*100,2)&" % : l'emplacement n'explique rien, l'écart venait de ces magasins."
B32: 2. Le mix canal bouge-t-il ?
B33: Part du CA net par canal et par trimestre civil (2024 T3 = septembre seul ; 2026 T3 = juillet–août).
B34: Trimestre | C34: Début | D34: Fin | E34: Sur place | F34: À emporter | G34: Livraison | H34: Drive
B35: 2024 T3 | C35: 45474 | D35: 45536 | E35: =SUMIFS(V_CANet,V_Mois,">="&$C35,V_Mois,"<="&$D35,V_Canal,E$34)/SUMIFS(V_CANet,V_Mois,">="&$C35,V_Mois,"<="&$D35) | F35: =SUMIFS(V_CANet,V_Mois,">="&$C35,V_Mois,"<="&$D35,V_Canal,F$34)/SUMIFS(V_CANet,V_Mois,">="&$C35,V_Mois,"<="&$D35) | G35: =SUMIFS(V_CANet,V_Mois,">="&$C35,V_Mois,"<="&$D35,V_Canal,G$34)/SUMIFS(V_CANet,V_Mois,">="&$C35,V_Mois,"<="&$D35) | H35: =SUMIFS(V_CANet,V_Mois,">="&$C35,V_Mois,"<="&$D35,V_Canal,H$34)/SUMIFS(V_CANet,V_Mois,">="&$C35,V_Mois,"<="&$D35)
B36: 2024 T4 | C36: 45566 | D36: 45627 | E36: =SUMIFS(V_CANet,V_Mois,">="&$C36,V_Mois,"<="&$D36,V_Canal,E$34)/SUMIFS(V_CANet,V_Mois,">="&$C36,V_Mois,"<="&$D36) | F36: =SUMIFS(V_CANet,V_Mois,">="&$C36,V_Mois,"<="&$D36,V_Canal,F$34)/SUMIFS(V_CANet,V_Mois,">="&$C36,V_Mois,"<="&$D36) | G36: =SUMIFS(V_CANet,V_Mois,">="&$C36,V_Mois,"<="&$D36,V_Canal,G$34)/SUMIFS(V_CANet,V_Mois,">="&$C36,V_Mois,"<="&$D36) | H36: =SUMIFS(V_CANet,V_Mois,">="&$C36,V_Mois,"<="&$D36,V_Canal,H$34)/SUMIFS(V_CANet,V_Mois,">="&$C36,V_Mois,"<="&$D36)
B37: 2025 T1 | C37: 45658 | D37: 45717 | E37: =SUMIFS(V_CANet,V_Mois,">="&$C37,V_Mois,"<="&$D37,V_Canal,E$34)/SUMIFS(V_CANet,V_Mois,">="&$C37,V_Mois,"<="&$D37) | F37: =SUMIFS(V_CANet,V_Mois,">="&$C37,V_Mois,"<="&$D37,V_Canal,F$34)/SUMIFS(V_CANet,V_Mois,">="&$C37,V_Mois,"<="&$D37) | G37: =SUMIFS(V_CANet,V_Mois,">="&$C37,V_Mois,"<="&$D37,V_Canal,G$34)/SUMIFS(V_CANet,V_Mois,">="&$C37,V_Mois,"<="&$D37) | H37: =SUMIFS(V_CANet,V_Mois,">="&$C37,V_Mois,"<="&$D37,V_Canal,H$34)/SUMIFS(V_CANet,V_Mois,">="&$C37,V_Mois,"<="&$D37)
B38: 2025 T2 | C38: 45748 | D38: 45809 | E38: =SUMIFS(V_CANet,V_Mois,">="&$C38,V_Mois,"<="&$D38,V_Canal,E$34)/SUMIFS(V_CANet,V_Mois,">="&$C38,V_Mois,"<="&$D38) | F38: =SUMIFS(V_CANet,V_Mois,">="&$C38,V_Mois,"<="&$D38,V_Canal,F$34)/SUMIFS(V_CANet,V_Mois,">="&$C38,V_Mois,"<="&$D38) | G38: =SUMIFS(V_CANet,V_Mois,">="&$C38,V_Mois,"<="&$D38,V_Canal,G$34)/SUMIFS(V_CANet,V_Mois,">="&$C38,V_Mois,"<="&$D38) | H38: =SUMIFS(V_CANet,V_Mois,">="&$C38,V_Mois,"<="&$D38,V_Canal,H$34)/SUMIFS(V_CANet,V_Mois,">="&$C38,V_Mois,"<="&$D38)
B39: 2025 T3 | C39: 45839 | D39: 45901 | E39: =SUMIFS(V_CANet,V_Mois,">="&$C39,V_Mois,"<="&$D39,V_Canal,E$34)/SUMIFS(V_CANet,V_Mois,">="&$C39,V_Mois,"<="&$D39) | F39: =SUMIFS(V_CANet,V_Mois,">="&$C39,V_Mois,"<="&$D39,V_Canal,F$34)/SUMIFS(V_CANet,V_Mois,">="&$C39,V_Mois,"<="&$D39) | G39: =SUMIFS(V_CANet,V_Mois,">="&$C39,V_Mois,"<="&$D39,V_Canal,G$34)/SUMIFS(V_CANet,V_Mois,">="&$C39,V_Mois,"<="&$D39) | H39: =SUMIFS(V_CANet,V_Mois,">="&$C39,V_Mois,"<="&$D39,V_Canal,H$34)/SUMIFS(V_CANet,V_Mois,">="&$C39,V_Mois,"<="&$D39)
B40: 2025 T4 | C40: 45931 | D40: 45992 | E40: =SUMIFS(V_CANet,V_Mois,">="&$C40,V_Mois,"<="&$D40,V_Canal,E$34)/SUMIFS(V_CANet,V_Mois,">="&$C40,V_Mois,"<="&$D40) | F40: =SUMIFS(V_CANet,V_Mois,">="&$C40,V_Mois,"<="&$D40,V_Canal,F$34)/SUMIFS(V_CANet,V_Mois,">="&$C40,V_Mois,"<="&$D40) | G40: =SUMIFS(V_CANet,V_Mois,">="&$C40,V_Mois,"<="&$D40,V_Canal,G$34)/SUMIFS(V_CANet,V_Mois,">="&$C40,V_Mois,"<="&$D40) | H40: =SUMIFS(V_CANet,V_Mois,">="&$C40,V_Mois,"<="&$D40,V_Canal,H$34)/SUMIFS(V_CANet,V_Mois,">="&$C40,V_Mois,"<="&$D40)
B41: 2026 T1 | C41: 46023 | D41: 46082 | E41: =SUMIFS(V_CANet,V_Mois,">="&$C41,V_Mois,"<="&$D41,V_Canal,E$34)/SUMIFS(V_CANet,V_Mois,">="&$C41,V_Mois,"<="&$D41) | F41: =SUMIFS(V_CANet,V_Mois,">="&$C41,V_Mois,"<="&$D41,V_Canal,F$34)/SUMIFS(V_CANet,V_Mois,">="&$C41,V_Mois,"<="&$D41) | G41: =SUMIFS(V_CANet,V_Mois,">="&$C41,V_Mois,"<="&$D41,V_Canal,G$34)/SUMIFS(V_CANet,V_Mois,">="&$C41,V_Mois,"<="&$D41) | H41: =SUMIFS(V_CANet,V_Mois,">="&$C41,V_Mois,"<="&$D41,V_Canal,H$34)/SUMIFS(V_CANet,V_Mois,">="&$C41,V_Mois,"<="&$D41)
B42: 2026 T2 | C42: 46113 | D42: 46174 | E42: =SUMIFS(V_CANet,V_Mois,">="&$C42,V_Mois,"<="&$D42,V_Canal,E$34)/SUMIFS(V_CANet,V_Mois,">="&$C42,V_Mois,"<="&$D42) | F42: =SUMIFS(V_CANet,V_Mois,">="&$C42,V_Mois,"<="&$D42,V_Canal,F$34)/SUMIFS(V_CANet,V_Mois,">="&$C42,V_Mois,"<="&$D42) | G42: =SUMIFS(V_CANet,V_Mois,">="&$C42,V_Mois,"<="&$D42,V_Canal,G$34)/SUMIFS(V_CANet,V_Mois,">="&$C42,V_Mois,"<="&$D42) | H42: =SUMIFS(V_CANet,V_Mois,">="&$C42,V_Mois,"<="&$D42,V_Canal,H$34)/SUMIFS(V_CANet,V_Mois,">="&$C42,V_Mois,"<="&$D42)
B43: 2026 T3 | C43: 46204 | D43: 46266 | E43: =SUMIFS(V_CANet,V_Mois,">="&$C43,V_Mois,"<="&$D43,V_Canal,E$34)/SUMIFS(V_CANet,V_Mois,">="&$C43,V_Mois,"<="&$D43) | F43: =SUMIFS(V_CANet,V_Mois,">="&$C43,V_Mois,"<="&$D43,V_Canal,F$34)/SUMIFS(V_CANet,V_Mois,">="&$C43,V_Mois,"<="&$D43) | G43: =SUMIFS(V_CANet,V_Mois,">="&$C43,V_Mois,"<="&$D43,V_Canal,G$34)/SUMIFS(V_CANet,V_Mois,">="&$C43,V_Mois,"<="&$D43) | H43: =SUMIFS(V_CANet,V_Mois,">="&$C43,V_Mois,"<="&$D43,V_Canal,H$34)/SUMIFS(V_CANet,V_Mois,">="&$C43,V_Mois,"<="&$D43)
B45: ="La livraison passe de "&FIXED(G35*100,1)&" % à "&FIXED(G43*100,1)&" % du CA net en "&ROWS(G35:G43)-1&" trimestres (+"&FIXED((G43-G35)*100,1)&" pt), prise sur le sur place ("&FIXED((E43-E35)*100,1)&" pt) et l'à emporter ("&FIXED((F43-F35)*100,1)&" pt). Le Drive est stable."
B49: 3. Quels fournisseurs dérivent ?
B50: Retard moyen de livraison (jours au-delà du délai contractuel) par semestre civil de commande. Commandes non livrées exclues.
F51: Début → | G51: 45474 | H51: 45658 | I51: 45839 | J51: 46023 | K51: 46204
F52: Fin → | G52: 45627 | H52: 45809 | I52: 45992 | J52: 46174 | K52: 46357
...

Sheet SIMULATEUR
B1: SIMULATEUR — combien mettre, où, pour récupérer la marge perdue ?
B2: Les magasins candidats sont les 8 plus forts reculs de taux de marge (constat 1). Hypothèses dans PARAMETRES ; décisions d'audit en colonne L (0/1).
B4: Modèle — un audit par magasin candidat | P4: Contraintes et objectif
B5: Code | C5: Ville | D5: Région | E5: CA net N | F5: Taux N | G5: Écart (pt) | H5: Marge manquante | I5: Coût audit | J5: Gain net | K5: Seuil récup. | L5: Décision | M5: Gain retenu | N5: Coût retenu | P5: Coût engagé | Q5: =N14 | R5: =IF(Q5<=Q6,"respectée","DÉPASSÉE")
B6: =INDEX(CM_Code_Magasin,MATCH(SMALL(CM_Cle_Derive,1),CM_Cle_Derive,0)) | C6: =INDEX(CM_Ville,MATCH(SMALL(CM_Cle_Derive,1),CM_Cle_Derive,0)) | D6: =INDEX(CM_Region,MATCH(SMALL(CM_Cle_Derive,1),CM_Cle_Derive,0)) | E6: =INDEX(CM_CA_Net_N,MATCH(SMALL(CM_Cle_Derive,1),CM_Cle_Derive,0)) | F6: =INDEX(CM_Taux_Marge_N,MATCH(SMALL(CM_Cle_Derive,1),CM_Cle_Derive,0)) | G6: =(D_Taux_Reseau-F6)*100 | H6: =E6*(D_Taux_Reseau-F6) | I6: =Cout_Audit | J6: =H6*Taux_Recup-I6 | K6: =IF(H6>0,I6/H6,"") | L6: 1 | M6: =L6*J6 | N6: =L6*I6 | P6: Enveloppe | Q6: =Enveloppe_Audit
B7: =INDEX(CM_Code_Magasin,MATCH(SMALL(CM_Cle_Derive,2),CM_Cle_Derive,0)) | C7: =INDEX(CM_Ville,MATCH(SMALL(CM_Cle_Derive,2),CM_Cle_Derive,0)) | D7: =INDEX(CM_Region,MATCH(SMALL(CM_Cle_Derive,2),CM_Cle_Derive,0)) | E7: =INDEX(CM_CA_Net_N,MATCH(SMALL(CM_Cle_Derive,2),CM_Cle_Derive,0)) | F7: =INDEX(CM_Taux_Marge_N,MATCH(SMALL(CM_Cle_Derive,2),CM_Cle_Derive,0)) | G7: =(D_Taux_Reseau-F7)*100 | H7: =E7*(D_Taux_Reseau-F7) | I7: =Cout_Audit | J7: =H7*Taux_Recup-I7 | K7: =IF(H7>0,I7/H7,"") | L7: 1 | M7: =L7*J7 | N7: =L7*I7
B8: =INDEX(CM_Code_Magasin,MATCH(SMALL(CM_Cle_Derive,3),CM_Cle_Derive,0)) | C8: =INDEX(CM_Ville,MATCH(SMALL(CM_Cle_Derive,3),CM_Cle_Derive,0)) | D8: =INDEX(CM_Region,MATCH(SMALL(CM_Cle_Derive,3),CM_Cle_Derive,0)) | E8: =INDEX(CM_CA_Net_N,MATCH(SMALL(CM_Cle_Derive,3),CM_Cle_Derive,0)) | F8: =INDEX(CM_Taux_Marge_N,MATCH(SMALL(CM_Cle_Derive,3),CM_Cle_Derive,0)) | G8: =(D_Taux_Reseau-F8)*100 | H8: =E8*(D_Taux_Reseau-F8) | I8: =Cout_Audit | J8: =H8*Taux_Recup-I8 | K8: =IF(H8>0,I8/H8,"") | L8: 1 | M8: =L8*J8 | N8: =L8*I8 | P8: Région | Q8: Candidats | R8: Retenus | S8: Contrainte ≥ 1
B9: =INDEX(CM_Code_Magasin,MATCH(SMALL(CM_Cle_Derive,4),CM_Cle_Derive,0)) | C9: =INDEX(CM_Ville,MATCH(SMALL(CM_Cle_Derive,4),CM_Cle_Derive,0)) | D9: =INDEX(CM_Region,MATCH(SMALL(CM_Cle_Derive,4),CM_Cle_Derive,0)) | E9: =INDEX(CM_CA_Net_N,MATCH(SMALL(CM_Cle_Derive,4),CM_Cle_Derive,0)) | F9: =INDEX(CM_Taux_Marge_N,MATCH(SMALL(CM_Cle_Derive,4),CM_Cle_Derive,0)) | G9: =(D_Taux_Reseau-F9)*100 | H9: =E9*(D_Taux_Reseau-F9) | I9: =Cout_Audit | J9: =H9*Taux_Recup-I9 | K9: =IF(H9>0,I9/H9,"") | L9: 1 | M9: =L9*J9 | N9: =L9*I9 | P9: Île-de-France | Q9: =COUNTIF($D$6:$D$13,P9) | R9: =COUNTIFS($D$6:$D$13,P9,$L$6:$L$13,1) | S9: =IF(Q9=0,"sans objet",IF(R9>=1,"respectée","NON RESPECTÉE"))
B10: =INDEX(CM_Code_Magasin,MATCH(SMALL(CM_Cle_Derive,5),CM_Cle_Derive,0)) | C10: =INDEX(CM_Ville,MATCH(SMALL(CM_Cle_Derive,5),CM_Cle_Derive,0)) | D10: =INDEX(CM_Region,MATCH(SMALL(CM_Cle_Derive,5),CM_Cle_Derive,0)) | E10: =INDEX(CM_CA_Net_N,MATCH(SMALL(CM_Cle_Derive,5),CM_Cle_Derive,0)) | F10: =INDEX(CM_Taux_Marge_N,MATCH(SMALL(CM_Cle_Derive,5),CM_Cle_Derive,0)) | G10: =(D_Taux_Reseau-F10)*100 | H10: =E10*(D_Taux_Reseau-F10) | I10: =Cout_Audit | J10: =H10*Taux_Recup-I10 | K10: =IF(H10>0,I10/H10,"") | L10: 1 | M10: =L10*J10 | N10: =L10*I10 | P10: Sud-Est | Q10: =COUNTIF($D$6:$D$13,P10) | R10: =COUNTIFS($D$6:$D$13,P10,$L$6:$L$13,1) | S10: =IF(Q10=0,"sans objet",IF(R10>=1,"respectée","NON RESPECTÉE"))
B11: =INDEX(CM_Code_Magasin,MATCH(SMALL(CM_Cle_Derive,6),CM_Cle_Derive,0)) | C11: =INDEX(CM_Ville,MATCH(SMALL(CM_Cle_Derive,6),CM_Cle_Derive,0)) | D11: =INDEX(CM_Region,MATCH(SMALL(CM_Cle_Derive,6),CM_Cle_Derive,0)) | E11: =INDEX(CM_CA_Net_N,MATCH(SMALL(CM_Cle_Derive,6),CM_Cle_Derive,0)) | F11: =INDEX(CM_Taux_Marge_N,MATCH(SMALL(CM_Cle_Derive,6),CM_Cle_Derive,0)) | G11: =(D_Taux_Reseau-F11)*100 | H11: =E11*(D_Taux_Reseau-F11) | I11: =Cout_Audit | J11: =H11*Taux_Recup-I11 | K11: =IF(H11>0,I11/H11,"") | L11: 0 | M11: =L11*J11 | N11: =L11*I11 | P11: Nord-Ouest | Q11: =COUNTIF($D$6:$D$13,P11) | R11: =COUNTIFS($D$6:$D$13,P11,$L$6:$L$13,1) | S11: =IF(Q11=0,"sans objet",IF(R11>=1,"respectée","NON RESPECTÉE"))
B12: =INDEX(CM_Code_Magasin,MATCH(SMALL(CM_Cle_Derive,7),CM_Cle_Derive,0)) | C12: =INDEX(CM_Ville,MATCH(SMALL(CM_Cle_Derive,7),CM_Cle_Derive,0)) | D12: =INDEX(CM_Region,MATCH(SMALL(CM_Cle_Derive,7),CM_Cle_Derive,0)) | E12: =INDEX(CM_CA_Net_N,MATCH(SMALL(CM_Cle_Derive,7),CM_Cle_Derive,0)) | F12: =INDEX(CM_Taux_Marge_N,MATCH(SMALL(CM_Cle_Derive,7),CM_Cle_Derive,0)) | G12: =(D_Taux_Reseau-F12)*100 | H12: =E12*(D_Taux_Reseau-F12) | I12: =Cout_Audit | J12: =H12*Taux_Recup-I12 | K12: =IF(H12>0,I12/H12,"") | L12: 0 | M12: =L12*J12 | N12: =L12*I12 | P12: Sud-Ouest | Q12: =COUNTIF($D$6:$D$13,P12) | R12: =COUNTIFS($D$6:$D$13,P12,$L$6:$L$13,1) | S12: =IF(Q12=0,"sans objet",IF(R12>=1,"respectée","NON RESPECTÉE"))
B13: =INDEX(CM_Code_Magasin,MATCH(SMALL(CM_Cle_Derive,8),CM_Cle_Derive,0)) | C13: =INDEX(CM_Ville,MATCH(SMALL(CM_Cle_Derive,8),CM_Cle_Derive,0)) | D13: =INDEX(CM_Region,MATCH(SMALL(CM_Cle_Derive,8),CM_Cle_Derive,0)) | E13: =INDEX(CM_CA_Net_N,MATCH(SMALL(CM_Cle_Derive,8),CM_Cle_Derive,0)) | F13: =INDEX(CM_Taux_Marge_N,MATCH(SMALL(CM_Cle_Derive,8),CM_Cle_Derive,0)) | G13: =(D_Taux_Reseau-F13)*100 | H13: =E13*(D_Taux_Reseau-F13) | I13: =Cout_Audit | J13: =H13*Taux_Recup-I13 | K13: =IF(H13>0,I13/H13,"") | L13: 0 | M13: =L13*J13 | N13: =L13*I13
B14: Total | H14: =SUM(H6:H13) | L14: =SUM(L6:L13) | M14: =SUM(M6:M13) | N14: =SUM(N6:N13) | P14: Gain net de la sélection | Q14: =M14
B15: Écart = taux du réseau − taux du magasin. Seuil récup. = part de l'écart à récupérer pour que l'audit se paie. Décisions pré-remplies avec l'optimum du Solveur au scénario central.
P16: Paramétrage du Solveur
B17: Quatre façons de choisir — ce que l'optimisation apporte | P17: Objectif : $M$14 — Max
B18: Stratégie | F18: Magasins | H18: Coût | J18: Gain net | L18: Lecture | P18: Cellules variables : $L$6:$L$13
B19: Auditer les 8 candidats | F19: =COUNT(H6:H13) | H19: =COUNT(H6:H13)*Cout_Audit | J19: =SUM(J6:J13) | L19: =IF(H19>Enveloppe_Audit,"hors enveloppe ("&FIXED(H19,0)&" € > "&FIXED(Enveloppe_Audit,0)&" €)","") | P19: Contrainte : $L$6:$L$13 = binaire
B20: Classement naïf : les plus gros écarts, jusqu'à l'enveloppe | F20: =MIN(INT(Enveloppe_Audit/Cout_Audit),COUNT(H6:H13)) | H20: =F20*Cout_Audit | J20: =SUMPRODUCT((H6:H13>=LARGE(H6:H13,F20))*J6:J13) | L20: ="dont "&SUMPRODUCT((H6:H13>=LARGE(H6:H13,F20))*(J6:J13<0))&" à perte" | P20: Contrainte : $N$14 <= Enveloppe_Audit
B21: Sans contrainte régionale : gains positifs seuls | F21: =COUNTIF(J6:J13,">0") | H21: =COUNTIF(J6:J13,">0")*Cout_Audit | J21: =SUMIF(J6:J13,">0") | L21: ="enveloppe non saturée" | P21: Contrainte : $R$9:$R$12 >= 1 là où Q > 0
B22: Sélection actuelle (colonne L) | F22: =L14 | H22: =N14 | J22: =M14 | L22: ="contrainte régionale : coût de "&FIXED(J21-J22,0)&" €" | P22: Méthode : Simplex PL (problème linéaire)
P23: Contrôle : remettre L6:L13 à 0 puis lancer le Solveur ; il retrouve la sélection pré-remplie.
B24: ="L'enveloppe permet "&INT(Enveloppe_Audit/Cout_Audit)&" audits, mais seuls "&COUNTIF(J6:J13,">0")&" magasins ont un gain positif : c'est la rentabilité unitaire de l'audit qui limite l'opération, pas le budget. On engage "&FIXED(N14,0)&" € sur "&FIXED(Enveloppe_Audit,0)&" €."
P25: La contrainte régionale s'écrit en pratique sur les seules lignes où Q > 0 (régions présentes parmi les candidats).
B27: Sensibilité du gain net de la sélection — taux de récupération × coût unitaire | L27: Scénarios
B28: récup. ↓ coût → | C28: 30000 | D28: 35000 | E28: 40000 | F28: 45000 | G28: 50000 | H28: 55000 | I28: 60000 | P28: Prudent | Q28: Central | R28: Volontariste
B29: 0.3 | C29: =$B29*SUMPRODUCT($H$6:$H$13,$L$6:$L$13)-C$28*$L$14 | D29: =$B29*SUMPRODUCT($H$6:$H$13,$L$6:$L$13)-D$28*$L$14 | E29: =$B29*SUMPRODUCT($H$6:$H$13,$L$6:$L$13)-E$28*$L$14 | F29: =$B29*SUMPRODUCT($H$6:$H$13,$L$6:$L$13)-F$28*$L$14 | G29: =$B29*SUMPRODUCT($H$6:$H$13,$L$6:$L$13)-G$28*$L$14 | H29: =$B29*SUMPRODUCT($H$6:$H$13,$L$6:$L$13)-H$28*$L$14 | I29: =$B29*SUMPRODUCT($H$6:$H$13,$L$6:$L$13)-I$28*$L$14 | L29: Taux de récupération | P29: 0.4 | Q29: =Taux_Recup | R29: 0.85
B30: 0.4 | C30: =$B30*SUMPRODUCT($H$6:$H$13,$L$6:$L$13)-C$28*$L$14 | D30: =$B30*SUMPRODUCT($H$6:$H$13,$L$6:$L$13)-D$28*$L$14 | E30: =$B30*SUMPRODUCT($H$6:$H$13,$L$6:$L$13)-E$28*$L$14 | F30: =$B30*SUMPRODUCT($H$6:$H$13,$L$6:$L$13)-F$28*$L$14 | G30: =$B30*SUMPRODUCT($H$6:$H$13,$L$6:$L$13)-G$28*$L$14 | H30: =$B30*SUMPRODUCT($H$6:$H$13,$L$6:$L$13)-H$28*$L$14 | I30: =$B30*SUMPRODUCT($H$6:$H$13,$L$6:$L$13)-I$28*$L$14 | L30: Coût unitaire de l'audit | P30: 48000 | Q30: =Cout_Audit | R30: 38000
B31: 0.5 | C31: =$B31*SUMPRODUCT($H$6:$H$13,$L$6:$L$13)-C$28*$L$14 | D31: =$B31*SUMPRODUCT($H$6:$H$13,$L$6:$L$13)-D$28*$L$14 | E31: =$B31*SUMPRODUCT($H$6:$H$13,$L$6:$L$13)-E$28*$L$14 | F31: =$B31*SUMPRODUCT($H$6:$H$13,$L$6:$L$13)-F$28*$L$14 | G31: =$B31*SUMPRODUCT($H$6:$H$13,$L$6:$L$13)-G$28*$L$14 | H31: =$B31*SUMPRODUCT($H$6:$H$13,$L$6:$L$13)-H$28*$L$14 | I31: =$B31*SUMPRODUCT($H$6:$H$13,$L$6:$L$13)-I$28*$L$14 | L31: Baisse des prix d'achat | P31: 0 | Q31: 0 | R31: =Remise_Fournisseur_Volontariste
B32: 0.6 | C32: =$B32*SUMPRODUCT($H$6:$H$13,$L$6:$L$13)-C$28*$L$14 | D32: =$B32*SUMPRODUCT($H$6:$H$13,$L$6:$L$13)-D$28*$L$14 | E32: =$B32*SUMPRODUCT($H$6:$H$13,$L$6:$L$13)-E$28*$L$14 | F32: =$B32*SUMPRODUCT($H$6:$H$13,$L$6:$L$13)-F$28*$L$14 | G32: =$B32*SUMPRODUCT($H$6:$H$13,$L$6:$L$13)-G$28*$L$14 | H32: =$B32*SUMPRODUCT($H$6:$H$13,$L$6:$L$13)-H$28*$L$14 | I32: =$B32*SUMPRODUCT($H$6:$H$13,$L$6:$L$13)-I$28*$L$14 | L32: Gain net de la sélection | P32: =P29*SUMPRODUCT($H$6:$H$13,$L$6:$L$13)-P30*$L$14+P31*SUMPRODUCT($E$6:$E$13*(1-$F$6:$F$13),$L$6:$L$13) | Q32: =Q29*SUMPRODUCT($H$6:$H$13,$L$6:$L$13)-Q30*$L$14+Q31*SUMPRODUCT($E$6:$E$13*(1-$F$6:$F$13),$L$6:$L$13) | R32: =R29*SUMPRODUCT($H$6:$H$13,$L$6:$L$13)-R30*$L$14+R31*SUMPRODUCT($E$6:$E$13*(1-$F$6:$F$13),$L$6:$L$13)
B33: 0.7 | C33: =$B33*SUMPRODUCT($H$6:$H$13,$L$6:$L$13)-C$28*$L$14 | D33: =$B33*SUMPRODUCT($H$6:$H$13,$L$6:$L$13)-D$28*$L$14 | E33: =$B33*SUMPRODUCT($H$6:$H$13,$L$6:$L$13)-E$28*$L$14 | F33: =$B33*SUMPRODUCT($H$6:$H$13,$L$6:$L$13)-F$28*$L$14 | G33: =$B33*SUMPRODUCT($H$6:$H$13,$L$6:$L$13)-G$28*$L$14 | H33: =$B33*SUMPRODUCT($H$6:$H$13,$L$6:$L$13)-H$28*$L$14 | I33: =$B33*SUMPRODUCT($H$6:$H$13,$L$6:$L$13)-I$28*$L$14 | L33: Volontariste : la baisse des prix d'achat s'applique au coût matière des magasins retenus.
B34: 0.8 | C34: =$B34*SUMPRODUCT($H$6:$H$13,$L$6:$L$13)-C$28*$L$14 | D34: =$B34*SUMPRODUCT($H$6:$H$13,$L$6:$L$13)-D$28*$L$14 | E34: =$B34*SUMPRODUCT($H$6:$H$13,$L$6:$L$13)-E$28*$L$14 | F34: =$B34*SUMPRODUCT($H$6:$H$13,$L$6:$L$13)-F$28*$L$14 | G34: =$B34*SUMPRODUCT($H$6:$H$13,$L$6:$L$13)-G$28*$L$14 | H34: =$B34*SUMPRODUCT($H$6:$H$13,$L$6:$L$13)-H$28*$L$14 | I34: =$B34*SUMPRODUCT($H$6:$H$13,$L$6:$L$13)-I$28*$L$14
B35: 0.9 | C35: =$B35*SUMPRODUCT($H$6:$H$13,$L$6:$L$13)-C$28*$L$14 | D35: =$B35*SUMPRODUCT($H$6:$H$13,$L$6:$L$13)-D$28*$L$14 | E35: =$B35*SUMPRODUCT($H$6:$H$13,$L$6:$L$13)-E$28*$L$14 | F35: =$B35*SUMPRODUCT($H$6:$H$13,$L$6:$L$13)-F$28*$L$14 | G35: =$B35*SUMPRODUCT($H$6:$H$13,$L$6:$L$13)-G$28*$L$14 | H35: =$B35*SUMPRODUCT($H$6:$H$13,$L$6:$L$13)-H$28*$L$14 | I35: =$B35*SUMPRODUCT($H$6:$H$13,$L$6:$L$13)-I$28*$L$14 | L35: Valeur cible (résultats attendus)
B36: 1 | C36: =$B36*SUMPRODUCT($H$6:$H$13,$L$6:$L$13)-C$28*$L$14 | D36: =$B36*SUMPRODUCT($H$6:$H$13,$L$6:$L$13)-D$28*$L$14 | E36: =$B36*SUMPRODUCT($H$6:$H$13,$L$6:$L$13)-E$28*$L$14 | F36: =$B36*SUMPRODUCT($H$6:$H$13,$L$6:$L$13)-F$28*$L$14 | G36: =$B36*SUMPRODUCT($H$6:$H$13,$L$6:$L$13)-G$28*$L$14 | H36: =$B36*SUMPRODUCT($H$6:$H$13,$L$6:$L$13)-H$28*$L$14 | I36: =$B36*SUMPRODUCT($H$6:$H$13,$L$6:$L$13)-I$28*$L$14 | L36: Point mort de la sélection (taux de récupération) | R36: =N14/SUMPRODUCT(H6:H13,L6:L13)
L37: ="Taux de coût matière qui ramène "&B6&" au seuil d'alerte" | R37: =1-D_Seuil_Taux_Alerte
B38: ="Point mort de la sélection : "&FIXED(N14/SUMPRODUCT(H6:H13,L6:L13)*100,1)&" % de récupération au coût central. Au coût maximal de la grille, il faut "&FIXED(MAX(C28:I28)*L14/SUMPRODUCT(H6:H13,L6:L13)*100,1)&" %." | L38: ="Taux de coût matière actuel de "&B6 | R38: =1-F6
B39: Grille écrite en formules explicites, équivalente à une table de données à deux entrées.
B41: Monte-Carlo — 1 000 tirages du taux de récupération (feuille MONTE_CARLO)
B42: Gain net moyen | E42: =AVERAGE(MONTE_CARLO!$S$4:$S$1003) | H42: Classe (gain net) | I42: Tirages
B43: Écart-type | E43: =STDEV(MONTE_CARLO!$S$4:$S$1003) | H43: -100000 | I43: =COUNTIFS(MONTE_CARLO!$S$4:$S$1003,"<="&H43,MONTE_CARLO!$S$4:$S$1003,">"&-1E+12)
...

Sheet MONTE_CARLO
A1: MONTE_CARLO — 1 000 tirages (fonctions volatiles : F9 pour relancer)
B2: Taux de récupération tirés | J2: Gain net par magasin (si retenu)
A3: Tirage | B3: ="r "&SIMULATEUR!B6 | C3: ="r "&SIMULATEUR!B7 | D3: ="r "&SIMULATEUR!B8 | E3: ="r "&SIMULATEUR!B9 | F3: ="r "&SIMULATEUR!B10 | G3: ="r "&SIMULATEUR!B11 | H3: ="r "&SIMULATEUR!B12 | I3: ="r "&SIMULATEUR!B13 | J3: ="gain "&SIMULATEUR!B6 | K3: ="gain "&SIMULATEUR!B7 | L3: ="gain "&SIMULATEUR!B8 | M3: ="gain "&SIMULATEUR!B9 | N3: ="gain "&SIMULATEUR!B10 | O3: ="gain "&SIMULATEUR!B11 | P3: ="gain "&SIMULATEUR!B12 | Q3: ="gain "&SIMULATEUR!B13 | S3: Gain total
A4: 1 | B4: =MAX(0,MIN(1,NORMINV(RAND(),Taux_Recup,Ecart_Type_Recup))) | C4: =MAX(0,MIN(1,NORMINV(RAND(),Taux_Recup,Ecart_Type_Recup))) | D4: =MAX(0,MIN(1,NORMINV(RAND(),Taux_Recup,Ecart_Type_Recup))) | E4: =MAX(0,MIN(1,NORMINV(RAND(),Taux_Recup,Ecart_Type_Recup))) | F4: =MAX(0,MIN(1,NORMINV(RAND(),Taux_Recup,Ecart_Type_Recup))) | G4: =MAX(0,MIN(1,NORMINV(RAND(),Taux_Recup,Ecart_Type_Recup))) | H4: =MAX(0,MIN(1,NORMINV(RAND(),Taux_Recup,Ecart_Type_Recup))) | I4: =MAX(0,MIN(1,NORMINV(RAND(),Taux_Recup,Ecart_Type_Recup))) | J4: =SIMULATEUR!$L$6*(SIMULATEUR!$H$6*B4-Cout_Audit) | K4: =SIMULATEUR!$L$7*(SIMULATEUR!$H$7*C4-Cout_Audit) | L4: =SIMULATEUR!$L$8*(SIMULATEUR!$H$8*D4-Cout_Audit) | M4: =SIMULATEUR!$L$9*(SIMULATEUR!$H$9*E4-Cout_Audit) | N4: =SIMULATEUR!$L$10*(SIMULATEUR!$H$10*F4-Cout_Audit) | O4: =SIMULATEUR!$L$11*(SIMULATEUR!$H$11*G4-Cout_Audit) | P4: =SIMULATEUR!$L$12*(SIMULATEUR!$H$12*H4-Cout_Audit) | Q4: =SIMULATEUR!$L$13*(SIMULATEUR!$H$13*I4-Cout_Audit) | S4: =SUM(J4:Q4)
A5: 2 | B5: =MAX(0,MIN(1,NORMINV(RAND(),Taux_Recup,Ecart_Type_Recup))) | C5: =MAX(0,MIN(1,NORMINV(RAND(),Taux_Recup,Ecart_Type_Recup))) | D5: =MAX(0,MIN(1,NORMINV(RAND(),Taux_Recup,Ecart_Type_Recup))) | E5: =MAX(0,MIN(1,NORMINV(RAND(),Taux_Recup,Ecart_Type_Recup))) | F5: =MAX(0,MIN(1,NORMINV(RAND(),Taux_Recup,Ecart_Type_Recup))) | G5: =MAX(0,MIN(1,NORMINV(RAND(),Taux_Recup,Ecart_Type_Recup))) | H5: =MAX(0,MIN(1,NORMINV(RAND(),Taux_Recup,Ecart_Type_Recup))) | I5: =MAX(0,MIN(1,NORMINV(RAND(),Taux_Recup,Ecart_Type_Recup))) | J5: =SIMULATEUR!$L$6*(SIMULATEUR!$H$6*B5-Cout_Audit) | K5: =SIMULATEUR!$L$7*(SIMULATEUR!$H$7*C5-Cout_Audit) | L5: =SIMULATEUR!$L$8*(SIMULATEUR!$H$8*D5-Cout_Audit) | M5: =SIMULATEUR!$L$9*(SIMULATEUR!$H$9*E5-Cout_Audit) | N5: =SIMULATEUR!$L$10*(SIMULATEUR!$H$10*F5-Cout_Audit) | O5: =SIMULATEUR!$L$11*(SIMULATEUR!$H$11*G5-Cout_Audit) | P5: =SIMULATEUR!$L$12*(SIMULATEUR!$H$12*H5-Cout_Audit) | Q5: =SIMULATEUR!$L$13*(SIMULATEUR!$H$13*I5-Cout_Audit) | S5: =SUM(J5:Q5)
A6: 3 | B6: =MAX(0,MIN(1,NORMINV(RAND(),Taux_Recup,Ecart_Type_Recup))) | C6: =MAX(0,MIN(1,NORMINV(RAND(),Taux_Recup,Ecart_Type_Recup))) | D6: =MAX(0,MIN(1,NORMINV(RAND(),Taux_Recup,Ecart_Type_Recup))) | E6: =MAX(0,MIN(1,NORMINV(RAND(),Taux_Recup,Ecart_Type_Recup))) | F6: =MAX(0,MIN(1,NORMINV(RAND(),Taux_Recup,Ecart_Type_Recup))) | G6: =MAX(0,MIN(1,NORMINV(RAND(),Taux_Recup,Ecart_Type_Recup))) | H6: =MAX(0,MIN(1,NORMINV(RAND(),Taux_Recup,Ecart_Type_Recup))) | I6: =MAX(0,MIN(1,NORMINV(RAND(),Taux_Recup,Ecart_Type_Recup))) | J6: =SIMULATEUR!$L$6*(SIMULATEUR!$H$6*B6-Cout_Audit) | K6: =SIMULATEUR!$L$7*(SIMULATEUR!$H$7*C6-Cout_Audit) | L6: =SIMULATEUR!$L$8*(SIMULATEUR!$H$8*D6-Cout_Audit) | M6: =SIMULATEUR!$L$9*(SIMULATEUR!$H$9*E6-Cout_Audit) | N6: =SIMULATEUR!$L$10*(SIMULATEUR!$H$10*F6-Cout_Audit) | O6: =SIMULATEUR!$L$11*(SIMULATEUR!$H$11*G6-Cout_Audit) | P6: =SIMULATEUR!$L$12*(SIMULATEUR!$H$12*H6-Cout_Audit) | Q6: =SIMULATEUR!$L$13*(SIMULATEUR!$H$13*I6-Cout_Audit) | S6: =SUM(J6:Q6)
A7: 4 | B7: =MAX(0,MIN(1,NORMINV(RAND(),Taux_Recup,Ecart_Type_Recup))) | C7: =MAX(0,MIN(1,NORMINV(RAND(),Taux_Recup,Ecart_Type_Recup))) | D7: =MAX(0,MIN(1,NORMINV(RAND(),Taux_Recup,Ecart_Type_Recup))) | E7: =MAX(0,MIN(1,NORMINV(RAND(),Taux_Recup,Ecart_Type_Recup))) | F7: =MAX(0,MIN(1,NORMINV(RAND(),Taux_Recup,Ecart_Type_Recup))) | G7: =MAX(0,MIN(1,NORMINV(RAND(),Taux_Recup,Ecart_Type_Recup))) | H7: =MAX(0,MIN(1,NORMINV(RAND(),Taux_Recup,Ecart_Type_Recup))) | I7: =MAX(0,MIN(1,NORMINV(RAND(),Taux_Recup,Ecart_Type_Recup))) | J7: =SIMULATEUR!$L$6*(SIMULATEUR!$H$6*B7-Cout_Audit) | K7: =SIMULATEUR!$L$7*(SIMULATEUR!$H$7*C7-Cout_Audit) | L7: =SIMULATEUR!$L$8*(SIMULATEUR!$H$8*D7-Cout_Audit) | M7: =SIMULATEUR!$L$9*(SIMULATEUR!$H$9*E7-Cout_Audit) | N7: =SIMULATEUR!$L$10*(SIMULATEUR!$H$10*F7-Cout_Audit) | O7: =SIMULATEUR!$L$11*(SIMULATEUR!$H$11*G7-Cout_Audit) | P7: =SIMULATEUR!$L$12*(SIMULATEUR!$H$12*H7-Cout_Audit) | Q7: =SIMULATEUR!$L$13*(SIMULATEUR!$H$13*I7-Cout_Audit) | S7: =SUM(J7:Q7)
A8: 5 | B8: =MAX(0,MIN(1,NORMINV(RAND(),Taux_Recup,Ecart_Type_Recup))) | C8: =MAX(0,MIN(1,NORMINV(RAND(),Taux_Recup,Ecart_Type_Recup))) | D8: =MAX(0,MIN(1,NORMINV(RAND(),Taux_Recup,Ecart_Type_Recup))) | E8: =MAX(0,MIN(1,NORMINV(RAND(),Taux_Recup,Ecart_Type_Recup))) | F8: =MAX(0,MIN(1,NORMINV(RAND(),Taux_Recup,Ecart_Type_Recup))) | G8: =MAX(0,MIN(1,NORMINV(RAND(),Taux_Recup,Ecart_Type_Recup))) | H8: =MAX(0,MIN(1,NORMINV(RAND(),Taux_Recup,Ecart_Type_Recup))) | I8: =MAX(0,MIN(1,NORMINV(RAND(),Taux_Recup,Ecart_Type_Recup))) | J8: =SIMULATEUR!$L$6*(SIMULATEUR!$H$6*B8-Cout_Audit) | K8: =SIMULATEUR!$L$7*(SIMULATEUR!$H$7*C8-Cout_Audit) | L8: =SIMULATEUR!$L$8*(SIMULATEUR!$H$8*D8-Cout_Audit) | M8: =SIMULATEUR!$L$9*(SIMULATEUR!$H$9*E8-Cout_Audit) | N8: =SIMULATEUR!$L$10*(SIMULATEUR!$H$10*F8-Cout_Audit) | O8: =SIMULATEUR!$L$11*(SIMULATEUR!$H$11*G8-Cout_Audit) | P8: =SIMULATEUR!$L$12*(SIMULATEUR!$H$12*H8-Cout_Audit) | Q8: =SIMULATEUR!$L$13*(SIMULATEUR!$H$13*I8-Cout_Audit) | S8: =SUM(J8:Q8)
A9: 6 | B9: =MAX(0,MIN(1,NORMINV(RAND(),Taux_Recup,Ecart_Type_Recup))) | C9: =MAX(0,MIN(1,NORMINV(RAND(),Taux_Recup,Ecart_Type_Recup))) | D9: =MAX(0,MIN(1,NORMINV(RAND(),Taux_Recup,Ecart_Type_Recup))) | E9: =MAX(0,MIN(1,NORMINV(RAND(),Taux_Recup,Ecart_Type_Recup))) | F9: =MAX(0,MIN(1,NORMINV(RAND(),Taux_Recup,Ecart_Type_Recup))) | G9: =MAX(0,MIN(1,NORMINV(RAND(),Taux_Recup,Ecart_Type_Recup))) | H9: =MAX(0,MIN(1,NORMINV(RAND(),Taux_Recup,Ecart_Type_Recup))) | I9: =MAX(0,MIN(1,NORMINV(RAND(),Taux_Recup,Ecart_Type_Recup))) | J9: =SIMULATEUR!$L$6*(SIMULATEUR!$H$6*B9-Cout_Audit) | K9: =SIMULATEUR!$L$7*(SIMULATEUR!$H$7*C9-Cout_Audit) | L9: =SIMULATEUR!$L$8*(SIMULATEUR!$H$8*D9-Cout_Audit) | M9: =SIMULATEUR!$L$9*(SIMULATEUR!$H$9*E9-Cout_Audit) | N9: =SIMULATEUR!$L$10*(SIMULATEUR!$H$10*F9-Cout_Audit) | O9: =SIMULATEUR!$L$11*(SIMULATEUR!$H$11*G9-Cout_Audit) | P9: =SIMULATEUR!$L$12*(SIMULATEUR!$H$12*H9-Cout_Audit) | Q9: =SIMULATEUR!$L$13*(SIMULATEUR!$H$13*I9-Cout_Audit) | S9: =SUM(J9:Q9)
A10: 7 | B10: =MAX(0,MIN(1,NORMINV(RAND(),Taux_Recup,Ecart_Type_Recup))) | C10: =MAX(0,MIN(1,NORMINV(RAND(),Taux_Recup,Ecart_Type_Recup))) | D10: =MAX(0,MIN(1,NORMINV(RAND(),Taux_Recup,Ecart_Type_Recup))) | E10: =MAX(0,MIN(1,NORMINV(RAND(),Taux_Recup,Ecart_Type_Recup))) | F10: =MAX(0,MIN(1,NORMINV(RAND(),Taux_Recup,Ecart_Type_Recup))) | G10: =MAX(0,MIN(1,NORMINV(RAND(),Taux_Recup,Ecart_Type_Recup))) | H10: =MAX(0,MIN(1,NORMINV(RAND(),Taux_Recup,Ecart_Type_Recup))) | I10: =MAX(0,MIN(1,NORMINV(RAND(),Taux_Recup,Ecart_Type_Recup))) | J10: =SIMULATEUR!$L$6*(SIMULATEUR!$H$6*B10-Cout_Audit) | K10: =SIMULATEUR!$L$7*(SIMULATEUR!$H$7*C10-Cout_Audit) | L10: =SIMULATEUR!$L$8*(SIMULATEUR!$H$8*D10-Cout_Audit) | M10: =SIMULATEUR!$L$9*(SIMULATEUR!$H$9*E10-Cout_Audit) | N10: =SIMULATEUR!$L$10*(SIMULATEUR!$H$10*F10-Cout_Audit) | O10: =SIMULATEUR!$L$11*(SIMULATEUR!$H$11*G10-Cout_Audit) | P10: =SIMULATEUR!$L$12*(SIMULATEUR!$H$12*H10-Cout_Audit) | Q10: =SIMULATEUR!$L$13*(SIMULATEUR!$H$13*I10-Cout_Audit) | S10: =SUM(J10:Q10)
A11: 8 | B11: =MAX(0,MIN(1,NORMINV(RAND(),Taux_Recup,Ecart_Type_Recup))) | C11: =MAX(0,MIN(1,NORMINV(RAND(),Taux_Recup,Ecart_Type_Recup))) | D11: =MAX(0,MIN(1,NORMINV(RAND(),Taux_Recup,Ecart_Type_Recup))) | E11: =MAX(0,MIN(1,NORMINV(RAND(),Taux_Recup,Ecart_Type_Recup))) | F11: =MAX(0,MIN(1,NORMINV(RAND(),Taux_Recup,Ecart_Type_Recup))) | G11: =MAX(0,MIN(1,NORMINV(RAND(),Taux_Recup,Ecart_Type_Recup))) | H11: =MAX(0,MIN(1,NORMINV(RAND(),Taux_Recup,Ecart_Type_Recup))) | I11: =MAX(0,MIN(1,NORMINV(RAND(),Taux_Recup,Ecart_Type_Recup))) | J11: =SIMULATEUR!$L$6*(SIMULATEUR!$H$6*B11-Cout_Audit) | K11: =SIMULATEUR!$L$7*(SIMULATEUR!$H$7*C11-Cout_Audit) | L11: =SIMULATEUR!$L$8*(SIMULATEUR!$H$8*D11-Cout_Audit) | M11: =SIMULATEUR!$L$9*(SIMULATEUR!$H$9*E11-Cout_Audit) | N11: =SIMULATEUR!$L$10*(SIMULATEUR!$H$10*F11-Cout_Audit) | O11: =SIMULATEUR!$L$11*(SIMULATEUR!$H$11*G11-Cout_Audit) | P11: =SIMULATEUR!$L$12*(SIMULATEUR!$H$12*H11-Cout_Audit) | Q11: =SIMULATEUR!$L$13*(SIMULATEUR!$H$13*I11-Cout_Audit) | S11: =SUM(J11:Q11)
A12: 9 | B12: =MAX(0,MIN(1,NORMINV(RAND(),Taux_Recup,Ecart_Type_Recup))) | C12: =MAX(0,MIN(1,NORMINV(RAND(),Taux_Recup,Ecart_Type_Recup))) | D12: =MAX(0,MIN(1,NORMINV(RAND(),Taux_Recup,Ecart_Type_Recup))) | E12: =MAX(0,MIN(1,NORMINV(RAND(),Taux_Recup,Ecart_Type_Recup))) | F12: =MAX(0,MIN(1,NORMINV(RAND(),Taux_Recup,Ecart_Type_Recup))) | G12: =MAX(0,MIN(1,NORMINV(RAND(),Taux_Recup,Ecart_Type_Recup))) | H12: =MAX(0,MIN(1,NORMINV(RAND(),Taux_Recup,Ecart_Type_Recup))) | I12: =MAX(0,MIN(1,NORMINV(RAND(),Taux_Recup,Ecart_Type_Recup))) | J12: =SIMULATEUR!$L$6*(SIMULATEUR!$H$6*B12-Cout_Audit) | K12: =SIMULATEUR!$L$7*(SIMULATEUR!$H$7*C12-Cout_Audit) | L12: =SIMULATEUR!$L$8*(SIMULATEUR!$H$8*D12-Cout_Audit) | M12: =SIMULATEUR!$L$9*(SIMULATEUR!$H$9*E12-Cout_Audit) | N12: =SIMULATEUR!$L$10*(SIMULATEUR!$H$10*F12-Cout_Audit) | O12: =SIMULATEUR!$L$11*(SIMULATEUR!$H$11*G12-Cout_Audit) | P12: =SIMULATEUR!$L$12*(SIMULATEUR!$H$12*H12-Cout_Audit) | Q12: =SIMULATEUR!$L$13*(SIMULATEUR!$H$13*I12-Cout_Audit) | S12: =SUM(J12:Q12)
A13: 10 | B13: =MAX(0,MIN(1,NORMINV(RAND(),Taux_Recup,Ecart_Type_Recup))) | C13: =MAX(0,MIN(1,NORMINV(RAND(),Taux_Recup,Ecart_Type_Recup))) | D13: =MAX(0,MIN(1,NORMINV(RAND(),Taux_Recup,Ecart_Type_Recup))) | E13: =MAX(0,MIN(1,NORMINV(RAND(),Taux_Recup,Ecart_Type_Recup))) | F13: =MAX(0,MIN(1,NORMINV(RAND(),Taux_Recup,Ecart_Type_Recup))) | G13: =MAX(0,MIN(1,NORMINV(RAND(),Taux_Recup,Ecart_Type_Recup))) | H13: =MAX(0,MIN(1,NORMINV(RAND(),Taux_Recup,Ecart_Type_Recup))) | I13: =MAX(0,MIN(1,NORMINV(RAND(),Taux_Recup,Ecart_Type_Recup))) | J13: =SIMULATEUR!$L$6*(SIMULATEUR!$H$6*B13-Cout_Audit) | K13: =SIMULATEUR!$L$7*(SIMULATEUR!$H$7*C13-Cout_Audit) | L13: =SIMULATEUR!$L$8*(SIMULATEUR!$H$8*D13-Cout_Audit) | M13: =SIMULATEUR!$L$9*(SIMULATEUR!$H$9*E13-Cout_Audit) | N13: =SIMULATEUR!$L$10*(SIMULATEUR!$H$10*F13-Cout_Audit) | O13: =SIMULATEUR!$L$11*(SIMULATEUR!$H$11*G13-Cout_Audit) | P13: =SIMULATEUR!$L$12*(SIMULATEUR!$H$12*H13-Cout_Audit) | Q13: =SIMULATEUR!$L$13*(SIMULATEUR!$H$13*I13-Cout_Audit) | S13: =SUM(J13:Q13)
A14: 11 | B14: =MAX(0,MIN(1,NORMINV(RAND(),Taux_Recup,Ecart_Type_Recup))) | C14: =MAX(0,MIN(1,NORMINV(RAND(),Taux_Recup,Ecart_Type_Recup))) | D14: =MAX(0,MIN(1,NORMINV(RAND(),Taux_Recup,Ecart_Type_Recup))) | E14: =MAX(0,MIN(1,NORMINV(RAND(),Taux_Recup,Ecart_Type_Recup))) | F14: =MAX(0,MIN(1,NORMINV(RAND(),Taux_Recup,Ecart_Type_Recup))) | G14: =MAX(0,MIN(1,NORMINV(RAND(),Taux_Recup,Ecart_Type_Recup))) | H14: =MAX(0,MIN(1,NORMINV(RAND(),Taux_Recup,Ecart_Type_Recup))) | I14: =MAX(0,MIN(1,NORMINV(RAND(),Taux_Recup,Ecart_Type_Recup))) | J14: =SIMULATEUR!$L$6*(SIMULATEUR!$H$6*B14-Cout_Audit) | K14: =SIMULATEUR!$L$7*(SIMULATEUR!$H$7*C14-Cout_Audit) | L14: =SIMULATEUR!$L$8*(SIMULATEUR!$H$8*D14-Cout_Audit) | M14: =SIMULATEUR!$L$9*(SIMULATEUR!$H$9*E14-Cout_Audit) | N14: =SIMULATEUR!$L$10*(SIMULATEUR!$H$10*F14-Cout_Audit) | O14: =SIMULATEUR!$L$11*(SIMULATEUR!$H$11*G14-Cout_Audit) | P14: =SIMULATEUR!$L$12*(SIMULATEUR!$H$12*H14-Cout_Audit) | Q14: =SIMULATEUR!$L$13*(SIMULATEUR!$H$13*I14-Cout_Audit) | S14: =SUM(J14:Q14)
A15: 12 | B15: =MAX(0,MIN(1,NORMINV(RAND(),Taux_Recup,Ecart_Type_Recup))) | C15: =MAX(0,MIN(1,NORMINV(RAND(),Taux_Recup,Ecart_Type_Recup))) | D15: =MAX(0,MIN(1,NORMINV(RAND(),Taux_Recup,Ecart_Type_Recup))) | E15: =MAX(0,MIN(1,NORMINV(RAND(),Taux_Recup,Ecart_Type_Recup))) | F15: =MAX(0,MIN(1,NORMINV(RAND(),Taux_Recup,Ecart_Type_Recup))) | G15: =MAX(0,MIN(1,NORMINV(RAND(),Taux_Recup,Ecart_Type_Recup))) | H15: =MAX(0,MIN(1,NORMINV(RAND(),Taux_Recup,Ecart_Type_Recup))) | I15: =MAX(0,MIN(1,NORMINV(RAND(),Taux_Recup,Ecart_Type_Recup))) | J15: =SIMULATEUR!$L$6*(SIMULATEUR!$H$6*B15-Cout_Audit) | K15: =SIMULATEUR!$L$7*(SIMULATEUR!$H$7*C15-Cout_Audit) | L15: =SIMULATEUR!$L$8*(SIMULATEUR!$H$8*D15-Cout_Audit) | M15: =SIMULATEUR!$L$9*(SIMULATEUR!$H$9*E15-Cout_Audit) | N15: =SIMULATEUR!$L$10*(SIMULATEUR!$H$10*F15-Cout_Audit) | O15: =SIMULATEUR!$L$11*(SIMULATEUR!$H$11*G15-Cout_Audit) | P15: =SIMULATEUR!$L$12*(SIMULATEUR!$H$12*H15-Cout_Audit) | Q15: =SIMULATEUR!$L$13*(SIMULATEUR!$H$13*I15-Cout_Audit) | S15: =SUM(J15:Q15)
... A1003: 1000 | B1003: =MAX(0,MIN(1,NORMINV(RAND(),Taux_Recup,Ecart_Type_Recup))) | C1003: =MAX(0,MIN(1,NORMINV(RAND(),Taux_Recup,Ecart_Type_Recup))) | D1003: =MAX(0,MIN(1,NORMINV(RAND(),Taux_Recup,Ecart_Type_Recup))) | E1003: =MAX(0,MIN(1,NORMINV(RAND(),Taux_Recup,Ecart_Type_Recup))) | F1003: =MAX(0,MIN(1,NORMINV(RAND(),Taux_Recup,Ecart_Type_Recup))) | G1003: =MAX(0,MIN(1,NORMINV(RAND(),Taux_Recup,Ecart_Type_Recup))) | H1003: =MAX(0,MIN(1,NORMINV(RAND(),Taux_Recup,Ecart_Type_Recup))) | I1003: =MAX(0,MIN(1,NORMINV(RAND(),Taux_Recup,Ecart_Type_Recup))) | J1003: =SIMULATEUR!$L$6*(SIMULATEUR!$H$6*B1003-Cout_Audit) | K1003: =SIMULATEUR!$L$7*(SIMULATEUR!$H$7*C1003-Cout_Audit) | L1003: =SIMULATEUR!$L$8*(SIMULATEUR!$H$8*D1003-Cout_Audit) | M1003: =SIMULATEUR!$L$9*(SIMULATEUR!$H$9*E1003-Cout_Audit) | N1003: =SIMULATEUR!$L$10*(SIMULATEUR!$H$10*F1003-Cout_Audit) | O1003: =SIMULATEUR!$L$11*(SIMULATEUR!$H$11*G1003-Cout_Audit) | P1003: =SIMULATEUR!$L$12*(SIMULATEUR!$H$12*H1003-Cout_Audit) | Q1003: =SIMULATEUR!$L$13*(SIMULATEUR!$H$13*I1003-Cout_Audit) | S1003: =SUM(J1003:Q1003)

Sheet PARAMETRES
B1: PARAMÈTRES — toutes les constantes du classeur
B2: Aucune formule du classeur ne contient de valeur en dur : seuils, dates et hypothèses vivent ici. Cellules en bleu sur fond jaune = saisissables.
B4: Cle | C4: Valeur | D4: Type | E4: Description
B5: Périmètre temporel
B6: Exercice_Courant | C6: 2025/26 | D6: Texte | E6: Exercice analysé (septembre → août).
B7: Exercice_Precedent | C7: 2024/25 | D7: Texte | E7: Exercice de comparaison N-1.
B8: Debut_Exercice | C8: 45901 | D8: Date | E8: Premier mois de l'exercice courant.
B9: Fin_Exercice | C9: 46265 | D9: Date | E9: Dernier jour de l'exercice courant.
B10: Debut_N1 | C10: 45536 | D10: Date | E10: Premier jour de l'exercice précédent. Sert aussi au périmètre comparable.
B11: Budget_Debut | C11: 46023 | D11: Date | E11: Premier mois du budget comparé (budget en année civile).
B12: Budget_Fin | C12: 46235 | D12: Date | E12: Dernier mois disponible du budget comparé.
B13: Periode_A_Debut | C13: 45536 | D13: Date | E13: Constat n°1 : début de la période de référence (sept.–déc. 2024).
B14: Periode_A_Fin | C14: 45627 | D14: Date | E14: Constat n°1 : fin de la période de référence.
B15: Periode_B_Debut | C15: 46023 | D15: Date | E15: Constat n°1 : début de la période récente (janv.–août 2026).
B16: Periode_B_Fin | C16: 46235 | D16: Date | E16: Constat n°1 : fin de la période récente.
B17: Seuils d'alerte
B18: Seuil_Alerte_Marge_Pt | C18: 0.02 | D18: Fraction | E18: Écart de taux de marge sous le réseau qui déclenche l'alerte (2 pt).
B19: Seuil_Derive_Marge_Pt | C19: -2 | D19: Points | E19: Recul de taux de marge entre périodes A et B qui classe un magasin « en dérive ».
B20: Seuil_Perte_Multiple_Mediane | C20: 2 | D20: Multiple | E20: Taux de perte anormal = plus de 2 fois la médiane du réseau. Un seuil fixe à 4 % manquerait HC-012 (3,45 %).
B21: Seuil_Atteinte_Budget | C21: 0.9 | D21: Fraction | E21: Atteinte budget sous laquelle un magasin est « sous objectif ».
B22: Seuil_Atteinte_Haute | C22: 1.05 | D22: Fraction | E22: Atteinte budget au-dessus de laquelle un magasin dépasse nettement l'objectif.
B23: Tolerance_Prix_Achat | C23: 0.01 | D23: Fraction | E23: Écart d'indice de prix d'achat au réseau toléré avant d'en faire une cause (±1 %).
B24: Tolerance_Mix_Livraison | C24: 0.05 | D24: Fraction | E24: Écart de part livraison au réseau toléré avant d'en faire une cause (±5 pt).
B25: Règles de gestion
B26: Taux_TVA_Restauration | C26: 0.1 | D26: Fraction | E26: TVA restauration. Alcools : 20 %.
B27: Hausse_Tarifaire | C27: 0.045 | D27: Fraction | E27: Hausse de prix appliquée au 01/09/2025. Source : REF_PRODUITS / Historique_Prix du référentiel.
B28: Date_Hausse_Tarifaire | C28: 45901 | D28: Date | E28: Date d'effet de la hausse tarifaire.
B29: Plafond_Remise | C29: 0.08 | D29: Fraction | E29: Remise maximale admise sur un relevé (contrôle du UserForm).
B30: Ratio_Articles_Min | C30: 1.8 | D30: Nombre | E30: Articles par ticket minimum plausible (contrôle de saisie).
B31: Ratio_Articles_Max | C31: 3.4 | D31: Nombre | E31: Articles par ticket maximum plausible (contrôle de saisie).
B32: Simulateur
B33: Cout_Audit | C33: 42000 | D33: Euros | E33: Coût d'un audit de cuisine par magasin : déplacement, formation, deux jours d'exploitation dégradée.
B34: Taux_Recup | C34: 0.65 | D34: Fraction | E34: Part de l'écart de marge récupérée par l'audit — scénario central.
B35: Ecart_Type_Recup | C35: 0.18 | D35: Fraction | E35: Incertitude sur le taux de récupération (écart-type de la loi normale, Monte-Carlo).
B36: Enveloppe_Audit | C36: 260000 | D36: Euros | E36: Budget disponible pour les audits.
B37: Remise_Fournisseur_Volontariste | C37: 0.015 | D37: Fraction | E37: Baisse des prix d'achat obtenue en renégociation (scénario volontariste).
B38: Couche VBA (à renseigner sur votre poste)
B39: Chemin_Donnees | C39: [À RENSEIGNER] C:\...\Horizon_Contrat\ | D39: Texte | E39: Dossier des fichiers sources. Lu par Power Query et par le VBA.
B40: Chemin_Sorties | C40: [À RENSEIGNER] C:\...\Sorties\ | D40: Texte | E40: Dossier où le VBA écrit les PDF.
B41: Mode_Envoi_Reel | C41: FALSE | D41: Booléen | E41: FAUX = les messages vont dans les brouillons Outlook. Ne passer à VRAI qu'une fois tout testé.
...

Sheet QUALITE
B1: QUALITÉ DES DONNÉES — ce que le nettoyage a trouvé et corrigé
B2: Section 1 : résultats du nettoyage (valeurs produites par le traitement, figées). Section 2 : contrôles recalculés en direct sur les feuilles DATA_*.
B4: 1. Résultats du nettoyage — fichiers sources
B5: Contrôle | C5: Valeur | D5: Traitement appliqué
B6: Lignes de ventes lues (24 fichiers) | C6: 289506 | D6: Lecture du dossier 02_Ventes, dates et décimales converties selon le format détecté ligne à ligne.
B7: Doublons stricts retirés | C7: 240 | D7: Tous dans Ventes_2025-07. Grain magasin × jour × canal : une combinaison ne peut pas apparaître deux fois.
B8: Lignes sans code magasin rejetées | C8: 422 | D8: Non récupérables. Détail par fichier ci-dessous.
B9: Lignes de ventes conservées | C9: 288844 | D9: Agrégées au mois dans DATA_VENTES.
B10: Fichiers au format de date JJ/MM/AAAA | C10: 3 | D10: Ventes_2024-11, Ventes_2025-04, Ventes_2026-01.
B11: Fichiers à virgule décimale | C11: 2 | D11: Ventes_2025-02, Ventes_2026-05.
B12: Doublons dans la feuille Magasins | C12: 2 | D12: Retirés : 122 → 120 magasins.
B13: Villes en casse incohérente corrigées | C13: 9 | D13: Casse de titre, particules en minuscule (Aix-en-Provence).
B14: Taux horaires stockés en texte | C14: 327 | D14: Convertis (symbole €, espace insécable, virgule), Moyenne après conversion : 13,82 €,
B15: Commandes sans date de livraison | C15: 2251 | D15: Conservées, exclues des calculs de retard (null, pas zéro).
B16: Lignes de budget après dépivotage | C16: 2880 | D16: 120 magasins × 12 mois × 2 années.
B19: Rejets par fichier (codes magasin vides)
B20: Fichier | C20: Lignes rejetées
B21: Ventes_2024-09.csv | C21: 17
B22: Ventes_2024-10.csv | C22: 18
B23: Ventes_2024-11.csv | C23: 17
B24: Ventes_2024-12.csv | C24: 18
B25: Ventes_2025-01.csv | C25: 18
B26: Ventes_2025-02.csv | C26: 16
B27: Ventes_2025-03.csv | C27: 18
B28: Ventes_2025-04.csv | C28: 17
B29: Ventes_2025-05.csv | C29: 18
B30: Ventes_2025-06.csv | C30: 17
B31: Ventes_2025-07.csv | C31: 18
B32: Ventes_2025-08.csv | C32: 18
... B44: Ventes_2026-08.csv | C44: 18
B45: Total | C45: =SUM(C21:C44)
B48: 2. Contrôles en direct sur les données chargées
B49: Contrôle | C49: Valeur | D49: Attendu
B50: Lignes de DATA_VENTES | C50: =COUNTA(V_Mag) | D50: Agrégat magasin × mois × canal.
B51: Magasins distincts dans REF_MAGASINS | C51: =SUMPRODUCT(1/COUNTIF(M_Code,M_Code)) | D51: 120
B52: CA net 24 mois (DATA_VENTES) | C52: =SUM(V_CANet) | D52: 301 027 972 € (CA net des 288 844 lignes conservées).
B53: Tickets 24 mois | C53: =SUM(V_Tickets) | D53: Somme des tickets.
B54: Lignes de DATA_BUDGET | C54: =COUNTA(B_Mag) | D54: 2 880
B55: Écart CA ventes / CA mix produits | C55: =SUM(X_CA)/SUM(V_CANet)-1 | D55: Sous 0,2 % (arrondis).
B56: Codes magasin de DATA_VENTES absents du référentiel | C56: =SUMPRODUCT(--(COUNTIF(M_Code,V_Mag)=0)) | D56: 0

Sheet _DOC
B1: DOCUMENTATION — Horizon_Contrat_Pilotage
B5: Objet
B6: Classeur | C6: Classeur de pilotage entièrement en formules. Il restitue 24 mois d'activité d'un réseau de 120 restaurants (sept. 2024 → août 2026) : tableau de bord, fiche magasin, sept constats, simulateur d'audit.
B7: Principe | C7: Aucun chiffre de restitution n'est saisi : tout est formule sur les feuilles DATA_* et REF_*. Les seules valeurs saisissables sont en bleu sur fond jaune (PARAMETRES, filtres, sélection du magasin, décisions du simulateur).
B9: Feuilles
